Workbook

Sheet 입찰리스트
A1: 분류 | B1: 구분 | C1: 내용
A2: 개요 | B2: 법원 | C2: 창원지방 | F2: 개인 | G2: 법인
B3: 지원 | C3: 통영 | F3: 1. 기일입찰표 | G3: 1. 기일입찰표
B4: 경매번호 | C4: 2024타경2243 | F4: 2. 위임장 | G4: 2. 위임장 | I4: 1 | J4: 카페입찰등록 업로드 | K4: 입찰표 사진
B5: 물건번호 | F5: 3. 인감 3개월이내, 6개월 이내면 해당계에 반드시 문의 | G5: 3. 법인사업자등록증 | I5: 2 | J5: MJ 경매 단톡방
B6: 입찰일자 | C6: 2025년10월20일 | F6: 4. 보증금 | G6: 4. 등기사항전부증명서 | J6: 낙찰: 영수증 사진업로드
A7: 입찰 | B7: 입찰가 | C7: 73900000 | G7: 5. 보증금 | J7: 패찰: 패찰알림
B8: 보증금 | C8: 7208500 | G8: * 법인등록증은 법인번호 확인 용도
B9: 진행비 | E9: 전자확인서=> | F9: 위임장 도장을 사인으로 대체,인감X 나머지 동일 | G9: 불가
B10: 회원명 | C10: 임준희
A11: 서류 기한안내 | B11: 서류제출 서류/기한 | C11: 20251017 오후 3시
B12: 보증금송금기한 | C12: 20251017 오후 1시
B13: 보증금 입금 계좌 | C13: 국민은행 07430204036633 이정우
A14: 개인 | B14: 입찰명의성명 | C14: 임준희
B15: 본인직업 | C15: 회사원
B16: 본인주민등록번호 | C16: 920408-1114428
B17: 본인전화번호 | C17: 010-8295-0129
B18: 본인주소 | C18: 경상남도 창원시 마산합포구 월영남5길 23(월영동)
B19: 본인계좌/보증금반환 | C19: 본인계좌
A20: 전자본인서명 확인서발급 | B20: 전자본인서명 확인서 발급 방법 | C20: https://www.youtube.com/watch?v=S2xVZjJeQd0&t=14s
B21: 전자서명본인확인서용도 | C21: =$C$2&"법원"&" "&$C$3&"지원"&" "&$C$4&IF($C$5="","",TEXT($C$5,"(0)"))&" "&"대리입찰" -> 창원지방법원 통영지원 2024타경2243 대리입찰
B22: 수임자 성명 | C22: =C32 -> 이정우
B23: 수임자 주소 | C23: =C36 -> 부산시 부산진구 전포대로 280 한성시티빌 1303호
B24: 수요법원 | C24: =$C$2&"법원"&" "&$C$3&"지원" -> 창원지방법원 통영지원
B25: 제출 방법 | C25: PDF 파일 다운로드 후 저에게 보내주세요
B26: 전사서명 유의사항 | C26: 전자서명 본신확인서 발급시 물건이 1개이상이면 물건번호별로 따로신청해야 됩니다.
A27: 법인 | B27: 법인성명 | C27: 법인성명
B28: 법인사업자번호 | C28: 법인사업자번호
B29: 법인등록번호 | C29: 법인등록번호
B30: 법인주소 | C30: 법인주소
B31: 법인계좌/보증금반환 | C31: 법인계좌
A32: 대리인 (수임자) | B32: 대리인성명 | C32: 이정우
B33: 대리인직업 | C33: 회사원
B34: 대리인주민등록번호 | C34: 780126-1851627
B35: 대리인전화번호 | C35: 010-4238-7781
B36: 대리인주소 | C36: 부산시 부산진구 전포대로 280 한성시티빌 1303호
B37: 대리인계좌번호 | C37: 국민은행 07430204036633 이정우
A50: 분류 | B50: 구분 | C50: 내용
A51: 입찰서류 | B51: 개인 | C51: 1. 기일입찰표
C52: 2. 보증금
...

Sheet 위임장-개인
A1: 위 임 장
A3: 대리인 | B3: 성 명 | D3: =입찰리스트!C32 -> 이정우 | H3: 직 업 | I3: =입찰리스트!C33 -> 회사원
B4: 주민등록번호 | D4: =입찰리스트!C34 -> 780126-1851627 | H4: 전화번호 | I4: =입찰리스트!C35 -> 010-4238-7781
B5: 주 소 | D5: =입찰리스트!C36 -> 부산시 부산진구 전포대로 280 한성시티빌 1303호
A7: 위 사람을 대리인으로 정하고 다음 사항을 위임함.
A9: 다 음
A11: =입찰리스트!C2 -> 창원지방 | C11: 지방법원 | E11: =입찰리스트!C3 -> 통영 | G11: 지원 | H11: =입찰리스트!C4 -> 2024타경2243 | K11: 호 | L11: =IF(입찰리스트!C5="","",TEXT(입찰리스트!C5,"(0)"))
A12: 위 경매사건에 관한 입찰행위 일체
F13: =입찰리스트!C6 -> 2025년10월20일
A16: 본인 | B16: 성 명 | D16: =입찰리스트!C14 -> 임준희 | H16: 직 업 | I16: =입찰리스트!C15 -> 회사원
B17: 주민등록번호 | D17: =입찰리스트!C16 -> 920408-1114428 | H17: 전화번호 | I17: =입찰리스트!C17 -> 010-8295-0129
B18: 주 소 | D18: =입찰리스트!C18 -> 경상남도 창원시 마산합포구 월영남5길 23(월영동)
G26: 서명 | H26: =입찰리스트!C14 -> 임준희 | L26: (인)
A28: 지방법원 귀중

Sheet 기일입찰표-개인
A1: [전산양식 A3360] 기일입찰표(흰색) 용지규격 210mmX297mm(A4용지)
A2: 기 일 입 찰 표
A3: =입찰리스트!C2 -> 창원지방 | C3: 지방법원 | G3: =입찰리스트!C3 -> 통영 | J3: 지원 집행관 귀하 | Q3: 입찰기일 : | U3: =입찰리스트!C6 -> 2025년10월20일
A4: 사건 번호 | C4: =입찰리스트!C4 -> 2024타경2243 | O4: 호 | P4: 물건 번호 | R4: =입찰리스트!C5 -> 0
A5: 입 찰 자 | B5: 본 인 | E5: 성 명 | K5: =입찰리스트!C14 -> 임준희 | R5: 전화번호 | V5: =입찰리스트!C17 -> 010-8295-0129
E7: 주민(사업자) 등 록 번 호 | K7: =입찰리스트!C16 -> 920408-1114428 | Q7: 법인등록 번 호
E8: 주 소 | K8: =입찰리스트!C18 -> 경상남도 창원시 마산합포구 월영남5길 23(월영동)
B10: 대리인 | E10: 성 명 | K10: =입찰리스트!C32 -> 이정우 | P10: (인) | R10: 본인과의 관 계 | V10: 지인
E12: 주민등록 번 호 | K12: =입찰리스트!C34 -> 780126-1851627 | R12: 전화번호 | V12: =입찰리스트!C35 -> 010-4238-7781
E14: 주 소 | K14: =입찰리스트!C36 -> 부산시 부산진구 전포대로 280 한성시티빌 1303호
A16: 입찰 가격 | B16: 천억 | C16: 백억 | D16: 십억 | E16: 억 | F16: 천만 | G16: 백만 | H16: 십만 | I16: 만 | J16: 천 | K16: 백 | L16: 십 | M16: 일 | N16: 원 | O16: 보증 금액 | P16: 백억 | Q16: 십억 | R16: 억 | S16: 천만 | T16: 백만 | U16: 십만 | V16: 만 | W16: 천 | X16: 백 | Y16: 십 | Z16: 일 | AA16: 원
B17: =IF(COLUMN(A1)<=12-LEN(입찰리스트!$C7),"",MID(입찰리스트!$C7,COLUMN(A1)-(12-LEN(입찰리스트!$C7)),1)) | C17: =IF(COLUMN(B1)<=12-LEN(입찰리스트!$C7),"",MID(입찰리스트!$C7,COLUMN(B1)-(12-LEN(입찰리스트!$C7)),1)) | D17: =IF(COLUMN(C1)<=12-LEN(입찰리스트!$C7),"",MID(입찰리스트!$C7,COLUMN(C1)-(12-LEN(입찰리스트!$C7)),1)) | E17: =IF(COLUMN(D1)<=12-LEN(입찰리스트!$C7),"",MID(입찰리스트!$C7,COLUMN(D1)-(12-LEN(입찰리스트!$C7)),1)) | F17: =IF(COLUMN(E1)<=12-LEN(입찰리스트!$C7),"",MID(입찰리스트!$C7,COLUMN(E1)-(12-LEN(입찰리스트!$C7)),1)) -> 7 | G17: =IF(COLUMN(F1)<=12-LEN(입찰리스트!$C7),"",MID(입찰리스트!$C7,COLUMN(F1)-(12-LEN(입찰리스트!$C7)),1)) -> 3 | H17: =IF(COLUMN(G1)<=12-LEN(입찰리스트!$C7),"",MID(입찰리스트!$C7,COLUMN(G1)-(12-LEN(입찰리스트!$C7)),1)) -> 9 | I17: =IF(COLUMN(H1)<=12-LEN(입찰리스트!$C7),"",MID(입찰리스트!$C7,COLUMN(H1)-(12-LEN(입찰리스트!$C7)),1)) -> 0 | ... M17: =IF(COLUMN(L1)<=12-LEN(입찰리스트!$C7),"",MID(입찰리스트!$C7,COLUMN(L1)-(12-LEN(입찰리스트!$C7)),1)) -> 0 | P17: =IF(COLUMN(A1)<=11-LEN(입찰리스트!$C8),"",MID(입찰리스트!$C8,COLUMN(A1)-(11-LEN(입찰리스트!$C8)),1)) | Q17: =IF(COLUMN(B1)<=11-LEN(입찰리스트!$C8),"",MID(입찰리스트!$C8,COLUMN(B1)-(11-LEN(입찰리스트!$C8)),1)) | R17: =IF(COLUMN(C1)<=11-LEN(입찰리스트!$C8),"",MID(입찰리스트!$C8,COLUMN(C1)-(11-LEN(입찰리스트!$C8)),1)) | S17: =IF(COLUMN(D1)<=11-LEN(입찰리스트!$C8),"",MID(입찰리스트!$C8,COLUMN(D1)-(11-LEN(입찰리스트!$C8)),1)) | T17: =IF(COLUMN(E1)<=11-LEN(입찰리스트!$C8),"",MID(입찰리스트!$C8,COLUMN(E1)-(11-LEN(입찰리스트!$C8)),1)) -> 7 | U17: =IF(COLUMN(F1)<=11-LEN(입찰리스트!$C8),"",MID(입찰리스트!$C8,COLUMN(F1)-(11-LEN(입찰리스트!$C8)),1)) -> 2 | V17: =IF(COLUMN(G1)<=11-LEN(입찰리스트!$C8),"",MID(입찰리스트!$C8,COLUMN(G1)-(11-LEN(입찰리스트!$C8)),1)) -> 0 | W17: =IF(COLUMN(H1)<=11-LEN(입찰리스트!$C8),"",MID(입찰리스트!$C8,COLUMN(H1)-(11-LEN(입찰리스트!$C8)),1)) -> 8 | ... Z17: =IF(COLUMN(K1)<=11-LEN(입찰리스트!$C8),"",MID(입찰리스트!$C8,COLUMN(K1)-(11-LEN(입찰리스트!$C8)),1)) -> 0
A19: 보증의 제공방법 | F19: V | G19: 현금,자기앞수표 | O19: 보증을 반환 받았습니다.
G20: 보증서
P22: 입찰자 대리인 | U22: =입찰리스트!C32 -> 이정우 | Z22: (인)
A25: 주의사항. 1. 입찰표는 물건마다 별도의 용지를 사용하십시오, 다만, 일괄입찰시에는 1매의 용지를 사용하십시오. 2. 한 사건에서 입찰물건이 여러개 있고 그 물건들이 개별적으로 입찰에 부쳐진 경우에는 사건번호외에 물건번호를 기재하십시오. 3. 입찰자가 법인인 경우에는 본인의 성명란에 법인의 명칭과 대표자의 지위 및 성명을, 주민등록란에는 입찰자가 개인인 경우에는 주민등록번호를, 법인인 경우에는 사업자등록번호를 기재하고, 대표자의 자격을 증명하는 서면(법인의 등기부 등․초본)을 제출하여야 합니다. 4. 주소는 주민등록상의 주소를, 법인은 등기부상의 본점소재지를 기재하시고, 신분확인상 필요하오니 주민등록증을 꼭 지참하십시오. 5. 입찰가격은 수정할 수 없으므로, 수정을 요하는 때에는 새 용지를 사용하십시오. 6. 대리인이 입찰하는 때에는 입찰자란에 본인과 대리인의 인적사항 및 본인과의 관계 등을 모두 기재하는 외에 본인의 "인감도장이 날인된" 위임장 인감증명을 제출하십시오. 7. 위임장, 인감증명 및 자격증명서는 이 입찰표에 첨부하십시오. 8. 일단 제출된 입찰표는 취소, 변경이나 교환이 불가능합니다. 9. 공동으로 입찰하는 경우에는 공동입찰신고서를 입찰표와 함께 제출하되, 입찰표의 본인란에는“별첨 공동입찰자목록 기재와 같음”이라고 기재한 다음, 입찰표와 공동입찰신고서 사이에는 공동입찰자 전원이 간인 하십시오. 10.입찰자 본인 또는 대리인 누구나 보증을 반환 받을 수 있습니다. 11.보증금의 제공밥법(현금,자기앞수표 또는 보증서)중 하나를 선택하여 V표를 기재하십시오.

Sheet 위임장-법인
A1: 위 임 장
A3: 대리인 | B3: 성 명 | D3: =입찰리스트!C32 -> 이정우 | H3: 직 업 | I3: =입찰리스트!C33 -> 회사원
B4: 주민등록번호 | D4: =입찰리스트!C34 -> 780126-1851627 | H4: 전화번호 | I4: =입찰리스트!C35 -> 010-4238-7781
B5: 주 소 | D5: =입찰리스트!C36 -> 부산시 부산진구 전포대로 280 한성시티빌 1303호
A7: 위 사람을 대리인으로 정하고 다음 사항을 위임함.
A9: 다 음
A11: =입찰리스트!C2 -> 창원지방 | C11: 지방법원 | E11: =입찰리스트!C3 -> 통영 | G11: 지원 | H11: =입찰리스트!C4 -> 2024타경2243 | K11: 호 | L11: =IF(입찰리스트!C5="","",TEXT(입찰리스트!C5,"(0)"))
A12: 위 경매사건에 관한 입찰행위 일체
F13: =입찰리스트!C6 -> 2025년10월20일
A16: 본인 | B16: 성 명 | D16: =입찰리스트!C27 -> 법인성명 | H16: 직 업 | I16: =입찰리스트!C15 -> 회사원
B17: 주민등록번호 | D17: =입찰리스트!C28 -> 법인사업자번호 | H17: 전화번호 | I17: =입찰리스트!C17 -> 010-8295-0129
B18: 주 소 | D18: =입찰리스트!C30 -> 법인주소
G26: 서명 | H26: =입찰리스트!C27 -> 법인성명 | L26: (인)
A28: 지방법원 귀중

Sheet 기일입찰표-법인
A1: [전산양식 A3360] 기일입찰표(흰색) 용지규격 210mmX297mm(A4용지)
A2: 기 일 입 찰 표
A3: =입찰리스트!C2 -> 창원지방 | C3: 지방법원 | G3: =입찰리스트!C3 -> 통영 | J3: 지원 집행관 귀하 | Q3: 입찰기일 : | U3: =입찰리스트!C6 -> 2025년10월20일
A4: 사건 번호 | C4: =입찰리스트!C4 -> 2024타경2243 | O4: 호 | P4: 물건 번호 | R4: =입찰리스트!C5 -> 0
A5: 입 찰 자 | B5: 본 인 | E5: 성 명 | K5: =입찰리스트!C27 -> 법인성명 | R5: 전화번호 | V5: =입찰리스트!C17 -> 010-8295-0129
E7: 주민(사업자) 등 록 번 호 | K7: =입찰리스트!C28 -> 법인사업자번호 | Q7: 법인등록 번 호 | T7: =입찰리스트!C29 -> 법인등록번호
E8: 주 소 | K8: =입찰리스트!C30 -> 법인주소
B10: 대리인 | E10: 성 명 | K10: =입찰리스트!C32 -> 이정우 | P10: (인) | R10: 본인과의 관 계 | V10: 지인
E12: 주민등록 번 호 | K12: =입찰리스트!C34 -> 780126-1851627 | R12: 전화번호 | V12: =입찰리스트!C35 -> 010-4238-7781
E14: 주 소 | K14: =입찰리스트!C36 -> 부산시 부산진구 전포대로 280 한성시티빌 1303호
A16: 입찰 가격 | B16: 천억 | C16: 백억 | D16: 십억 | E16: 억 | F16: 천만 | G16: 백만 | H16: 십만 | I16: 만 | J16: 천 | K16: 백 | L16: 십 | M16: 일 | N16: 원 | O16: 보증 금액 | P16: 백억 | Q16: 십억 | R16: 억 | S16: 천만 | T16: 백만 | U16: 십만 | V16: 만 | W16: 천 | X16: 백 | Y16: 십 | Z16: 일 | AA16: 원
B17: =IF(COLUMN(A1)<=12-LEN(입찰리스트!$C7),"",MID(입찰리스트!$C7,COLUMN(A1)-(12-LEN(입찰리스트!$C7)),1)) | C17: =IF(COLUMN(B1)<=12-LEN(입찰리스트!$C7),"",MID(입찰리스트!$C7,COLUMN(B1)-(12-LEN(입찰리스트!$C7)),1)) | D17: =IF(COLUMN(C1)<=12-LEN(입찰리스트!$C7),"",MID(입찰리스트!$C7,COLUMN(C1)-(12-LEN(입찰리스트!$C7)),1)) | E17: =IF(COLUMN(D1)<=12-LEN(입찰리스트!$C7),"",MID(입찰리스트!$C7,COLUMN(D1)-(12-LEN(입찰리스트!$C7)),1)) | F17: =IF(COLUMN(E1)<=12-LEN(입찰리스트!$C7),"",MID(입찰리스트!$C7,COLUMN(E1)-(12-LEN(입찰리스트!$C7)),1)) -> 7 | G17: =IF(COLUMN(F1)<=12-LEN(입찰리스트!$C7),"",MID(입찰리스트!$C7,COLUMN(F1)-(12-LEN(입찰리스트!$C7)),1)) -> 3 | H17: =IF(COLUMN(G1)<=12-LEN(입찰리스트!$C7),"",MID(입찰리스트!$C7,COLUMN(G1)-(12-LEN(입찰리스트!$C7)),1)) -> 9 | I17: =IF(COLUMN(H1)<=12-LEN(입찰리스트!$C7),"",MID(입찰리스트!$C7,COLUMN(H1)-(12-LEN(입찰리스트!$C7)),1)) -> 0 | ... M17: =IF(COLUMN(L1)<=12-LEN(입찰리스트!$C7),"",MID(입찰리스트!$C7,COLUMN(L1)-(12-LEN(입찰리스트!$C7)),1)) -> 0 | P17: =IF(COLUMN(A1)<=11-LEN(입찰리스트!$C8),"",MID(입찰리스트!$C8,COLUMN(A1)-(11-LEN(입찰리스트!$C8)),1)) | Q17: =IF(COLUMN(B1)<=11-LEN(입찰리스트!$C8),"",MID(입찰리스트!$C8,COLUMN(B1)-(11-LEN(입찰리스트!$C8)),1)) | R17: =IF(COLUMN(C1)<=11-LEN(입찰리스트!$C8),"",MID(입찰리스트!$C8,COLUMN(C1)-(11-LEN(입찰리스트!$C8)),1)) | S17: =IF(COLUMN(D1)<=11-LEN(입찰리스트!$C8),"",MID(입찰리스트!$C8,COLUMN(D1)-(11-LEN(입찰리스트!$C8)),1)) | T17: =IF(COLUMN(E1)<=11-LEN(입찰리스트!$C8),"",MID(입찰리스트!$C8,COLUMN(E1)-(11-LEN(입찰리스트!$C8)),1)) -> 7 | U17: =IF(COLUMN(F1)<=11-LEN(입찰리스트!$C8),"",MID(입찰리스트!$C8,COLUMN(F1)-(11-LEN(입찰리스트!$C8)),1)) -> 2 | V17: =IF(COLUMN(G1)<=11-LEN(입찰리스트!$C8),"",MID(입찰리스트!$C8,COLUMN(G1)-(11-LEN(입찰리스트!$C8)),1)) -> 0 | W17: =IF(COLUMN(H1)<=11-LEN(입찰리스트!$C8),"",MID(입찰리스트!$C8,COLUMN(H1)-(11-LEN(입찰리스트!$C8)),1)) -> 8 | ... Z17: =IF(COLUMN(K1)<=11-LEN(입찰리스트!$C8),"",MID(입찰리스트!$C8,COLUMN(K1)-(11-LEN(입찰리스트!$C8)),1)) -> 0
A19: 보증의 제공방법 | F19: V | G19: 현금,자기앞수표 | O19: 보증을 반환 받았습니다.
G20: 보증서
P22: 입찰자 대리인 | U22: =입찰리스트!C32 -> 이정우 | Z22: (인)
A25: 주의사항. 1. 입찰표는 물건마다 별도의 용지를 사용하십시오, 다만, 일괄입찰시에는 1매의 용지를 사용하십시오. 2. 한 사건에서 입찰물건이 여러개 있고 그 물건들이 개별적으로 입찰에 부쳐진 경우에는 사건번호외에 물건번호를 기재하십시오. 3. 입찰자가 법인인 경우에는 본인의 성명란에 법인의 명칭과 대표자의 지위 및 성명을, 주민등록란에는 입찰자가 개인인 경우에는 주민등록번호를, 법인인 경우에는 사업자등록번호를 기재하고, 대표자의 자격을 증명하는 서면(법인의 등기부 등․초본)을 제출하여야 합니다. 4. 주소는 주민등록상의 주소를, 법인은 등기부상의 본점소재지를 기재하시고, 신분확인상 필요하오니 주민등록증을 꼭 지참하십시오. 5. 입찰가격은 수정할 수 없으므로, 수정을 요하는 때에는 새 용지를 사용하십시오. 6. 대리인이 입찰하는 때에는 입찰자란에 본인과 대리인의 인적사항 및 본인과의 관계 등을 모두 기재하는 외에 본인의 "인감도장이 날인된" 위임장 인감증명을 제출하십시오. 7. 위임장, 인감증명 및 자격증명서는 이 입찰표에 첨부하십시오. 8. 일단 제출된 입찰표는 취소, 변경이나 교환이 불가능합니다. 9. 공동으로 입찰하는 경우에는 공동입찰신고서를 입찰표와 함께 제출하되, 입찰표의 본인란에는“별첨 공동입찰자목록 기재와 같음”이라고 기재한 다음, 입찰표와 공동입찰신고서 사이에는 공동입찰자 전원이 간인 하십시오. 10.입찰자 본인 또는 대리인 누구나 보증을 반환 받을 수 있습니다. 11.보증금의 제공밥법(현금,자기앞수표 또는 보증서)중 하나를 선택하여 V표를 기재하십시오.

Sheet Sheet2
A1: 권역 법원 거리(km) 비용(거리*4) 왕복경비(금액)
A2: 강릉지원 347 1388 2776 270,000
A3: 가정지원 168 672 1344 150,000
A4: 경주지원 81 324 648 100,000
A5: 고양지원 423 1692 3384 270,000
A6: 고창지원 423 1156 2312 230,000
A7: 광주지방법원 255 1020 2040 200,000
A8: 군산지원 256 1104 2360 230,000
A9: 구미지원 183 732 1464 160,000
A10: 김천지원 208 832 1664 160,000
A11: 논산지원 285 1140 2280 220,000
A12: 대구지방법원 335 1340 2680 250,000
... A54: 부산지법 12 12 24 70,000
